<?xml version="1.0" ?>

<robot name="morphing_robust">

  <material name="white">
    <color rgba="1. 1. 1. 1.0"/>
  </material>

  <material name="black">
    <color rgba="0. 0. 0. 1.0"/>
  </material>

  <material name="blue0">
    <color rgba="15./255. 141./255. 238./255. 1.0"/>
  </material>

  <material name="darkgrey">
    <color rgba="0.4 0.4 0.4 1.0"/>
  </material>

  <material name="blue1">
    <color rgba="0.06 0.46 0.9 0.6"/>
  </material>

  <configuration type="morphing_hexa"/>

  <properties arm="1.0635" kf="1.9e-8" km="1.9e-9" thrust2weight="4" max_speed_kmh="30" gnd_eff_coeff="11.36859" prop_radius="6.7e-2" drag_coeff_xy="9.1785e-7" drag_coeff_z="10.311e-7" dw_coeff_1="2267.18" dw_coeff_2=".16" dw_coeff_3="-.11"/>

  <control>
    <indi actuator_nr="6" output_nr="4" />
    <indi_1 roll="  -7.5   -15.0  -7.5   7.5  15.0  7.5" />
    <indi_2 pitch=" -13.0   0.0   13.0  13.0   0.0 -13.0" />
    <indi_3 yaw="   -5.0    5.0   -5.0   5.0  -5.0   5.0" />
    <indi_4 thrust=" 1.7    1.7    1.7   1.7   1.7   1.7" />
<!-- -1 Y    <indi_1 roll="  0. -13.0 -13.0  13.0  13.0  0.0" />
    <indi_2 pitch=" -15.0   13.0  13.0  13.0   13.0 -15.0" />
    <indi_3 yaw="   -5.0    5.0  -5.0   5.0  -5.0   5.0" />
    <indi_4 thrust=" 1.7    1.7   1.7   1.7   1.7   1.7" /> -->
<!--     <indi_1 roll="  -8.0 -15.0 -8.0  8.0  15.0  8.0" />
    <indi_2 pitch=" -15.0   0.0  15.0  15.0   0.0 -15.0" />
    <indi_3 yaw="   -5.0    5.0  -5.0   5.0  -5.0   5.0" />
    <indi_4 thrust=" 1.7    1.7   1.7   1.7   1.7   1.7" /> -->

    <indi_guidance_gains>
      <pos kp="1.7" kd="2.5"/>
    </indi_guidance_gains>

    <indi_att_gains>
      <att  p="10." q="10." r="5." />
      <rate p="18." q="18." r="12." />
    </indi_att_gains>

    <pwm>
      <pwm2rpm scale="20000. 20000. 20000. 20000. 20000. 20000." const="0. 0. 0. 0. 0. 0." />
      <limit min="0. 0. 0. 0. 0. 0." max="1. 1. 1. 1. 1. 1." />
    </pwm>
  </control>



  <link name="mainbody">
    <visual>
      <geometry>
        <cylinder radius=".071" length=".02"/>
        <origin rpy="0 0 0" xyz="0.0 0.0 0.01"/>
      </geometry>
<!--       <geometry>
        <box size="0.2 0.01 0.01"/>
        <origin rpy="0 0 0" xyz="0.10 0.0 0.0"/>
      </geometry> -->
      <material name="blue">
        <color rgba="0 0 .8 1"/>
      </material>
    </visual>
    <collision>
      <geometry>
          <cylinder radius=".07" length=".02"/>
      </geometry>
      <origin xyz="0.0 0.0 0.0"/>
    </collision>
    <inertial>
      <mass value="0.2"/>
      <inertia ixx="2.0e-3" ixy="0.0" ixz="0.0" iyy="2.0e-3" iyz="0.0" izz="4.0e-3"/>
    </inertial>
  </link>

<link name="prop1">
    <visual>
      <geometry>
        <cylinder radius=".062" length=".002"/>
        <origin rpy="0 0 0" xyz="0.0 0.0 0.0"/>
      </geometry>
      <material name="green">
        <color rgba="0 1 0 0.4"/>
      </material>
    </visual>
    <inertial>
    <origin xyz="0.0 0.0 0.001"/>
      <mass value="0.03"/>
      <inertia ixx="1.0e-9" ixy="0.0" ixz="0.0" iyy="1.0e-9" iyz="0.0" izz="1.0e-9"/>
    </inertial>
     <collision>
      <geometry>
        <cylinder radius=".062" length=".002"/>
      </geometry>
      <origin rpy="0 0 0" xyz="0.0 0.0 0.001"/>
    </collision>
  </link>

<link name="prop2">
    <visual>
      <geometry>
        <cylinder radius=".062" length=".002"/>
        <origin rpy="0 0 0" xyz="0.0 0.0 0.0"/>
      </geometry>
      <material name="orange red">
        <color rgba="1 0.25 0 0.4"/>
      </material>
    </visual>
    <inertial>
    <origin xyz="0.0 0.0 0.001"/>
      <mass value="0.03"/>
      <inertia ixx="1.0e-9" ixy="0.0" ixz="0.0" iyy="1.0e-9" iyz="0.0" izz="1.0e-9"/>
    </inertial>
     <collision>
      <geometry>
        <cylinder radius=".062" length=".002"/>
      </geometry>
      <origin rpy="0 0 0" xyz="0.0 0.0 0.001"/>
    </collision>
  </link>

<link name="prop3">
    <visual>
      <geometry>
        <cylinder radius=".062" length=".002"/>
        <origin rpy="0 0 0" xyz="0.0 0.0 0.0"/>
      </geometry>
      <material name="blue_t">
        <color rgba="0 0 0.8 0.4"/>
      </material>
    </visual>
    <inertial>
    <origin xyz="0.0 0.0 0.001"/>
      <mass value="0.03"/>
      <inertia ixx="1.0e-9" ixy="0.0" ixz="0.0" iyy="1.0e-9" iyz="0.0" izz="1.0e-9"/>
    </inertial>
     <collision>
      <geometry>
        <cylinder radius=".062" length=".002"/>
      </geometry>
      <origin rpy="0 0 0" xyz="0.0 0.0 0.001"/>
    </collision>
  </link>

<link name="prop4">
    <visual>
      <geometry>
        <cylinder radius=".062" length=".002"/>
        <origin rpy="0 0 0" xyz="0.0 0.0 0.0"/>
      </geometry>
      <material name="green">
        <color rgba="0 1 0 0.4"/>
      </material>
    </visual>
    <inertial>
    <origin xyz="0.0 0.0 0.001"/>
      <mass value="0.03"/>
      <inertia ixx="1.0e-9" ixy="0.0" ixz="0.0" iyy="1.0e-9" iyz="0.0" izz="1.0e-9"/>
    </inertial>
     <collision>
      <geometry>
        <cylinder radius=".062" length=".002"/>
      </geometry>
      <origin rpy="0 0 0" xyz="0.0 0.0 0.001"/>
    </collision>
  </link>

<link name="prop5">
    <visual>
      <geometry>
        <cylinder radius=".062" length=".002"/>
        <origin rpy="0 0 0" xyz="0.0 0.0 0.0"/>
      </geometry>
      <material name="orange red">
        <color rgba="1 0.25 0 0.4"/>
      </material>
    </visual>
    <inertial>
    <origin xyz="0.0 0.0 0.001"/>
      <mass value="0.03"/>
      <inertia ixx="1.0e-9" ixy="0.0" ixz="0.0" iyy="1.0e-9" iyz="0.0" izz="1.0e-9"/>
    </inertial>
     <collision>
      <geometry>
        <cylinder radius=".062" length=".002"/>
      </geometry>
      <origin rpy="0 0 0" xyz="0.0 0.0 0.001"/>
    </collision>
  </link>

<link name="prop6">
    <visual>
      <geometry>
        <cylinder radius=".062" length=".002"/>
        <origin rpy="0 0 0" xyz="0.0 0.0 0.0"/>
      </geometry>
      <material name="blue_t">
        <color rgba="0 0 0.8 0.4"/>
      </material>
    </visual>
    <inertial>
    <origin xyz="0.0 0.0 0.001"/>
      <mass value="0.03"/>
      <inertia ixx="1.0e-9" ixy="0.0" ixz="0.0" iyy="1.0e-9" iyz="0.0" izz="1.0e-9"/>
    </inertial>
     <collision>
      <geometry>
        <cylinder radius=".062" length=".002"/>
      </geometry>
      <origin rpy="0 0 0" xyz="0.0 0.0 0.001"/>
    </collision>
  </link>

  <link name="landinggear">
    <visual>
      <geometry>
        <box size="0.06 0.06 0.06"/>
        <origin rpy="0 0 0" xyz="0.0 0.0 0.0"/>
      </geometry>
      <material name="blue">
        <color rgba="0 0 .8 1"/>
      </material>
    </visual>
    <collision>
      <geometry>
          <box size="0.06 0.06 0.06"/>
      </geometry>
      <origin xyz="0.0 0.0 0.0"/>
    </collision>
    <inertial>
      <mass value="0.3"/>
      <inertia ixx="1.0e-9" ixy="0.0" ixz="0.0" iyy="1.0e-9" iyz="0.0" izz="1.0e-9"/>
    </inertial>
  </link>

<link name="arm1">
    <visual>
      <geometry>
        <box size="0.08 0.02 0.02"/>
      </geometry>
      <origin rpy="0 0 0" xyz="0.04 0.0 0.0"/>
      <material name="white">
        <color rgba="1 1 1 1"/>
      </material>
    </visual>
    <inertial>
    <origin xyz="0.04 0.01 0.01"/>
      <mass value="0.03"/>
      <inertia ixx="1.0e-9" ixy="0.0" ixz="0.0" iyy="1.0e-9" iyz="0.0" izz="1.0e-9"/>
    </inertial>
     <collision>
      <geometry>
        <box size="0.08 0.02 0.02"/>
      </geometry>
      <origin rpy="0 0 0" xyz="0.04 0.01 0.01"/>
    </collision>
  </link>

<link name="arm2">
    <visual>
      <geometry>
        <box size="0.08 0.02 0.02"/>
      </geometry>
      <origin rpy="0 0 0" xyz="0.04 0.0 0.0"/>
      <material name="white">
        <color rgba="1 1 1 1"/>
      </material>
    </visual>
    <inertial>
    <origin xyz="0.04 0.01 0.01"/>
      <mass value="0.03"/>
      <inertia ixx="1.0e-9" ixy="0.0" ixz="0.0" iyy="1.0e-9" iyz="0.0" izz="1.0e-9"/>
    </inertial>
     <collision>
      <geometry>
        <box size="0.08 0.02 0.02"/>
      </geometry>
      <origin rpy="0 0 0" xyz="0.04 0.01 0.01"/>
    </collision>
  </link>

  <link name="arm3">
    <visual>
      <geometry>
        <box size="0.08 0.02 0.02"/>
      </geometry>
      <origin rpy="0 0 0" xyz="0.04 0.0 0.0"/>
      <material name="white">
        <color rgba="1 1 1 1"/>
      </material>
    </visual>
    <inertial>
    <origin xyz="0.04 0.01 0.01"/>
      <mass value="0.03"/>
      <inertia ixx="1.0e-9" ixy="0.0" ixz="0.0" iyy="1.0e-9" iyz="0.0" izz="1.0e-9"/>
    </inertial>
     <collision>
      <geometry>
        <box size="0.08 0.02 0.02"/>
      </geometry>
      <origin rpy="0 0 0" xyz="0.04 0.01 0.01"/>
    </collision>
  </link>

    <link name="arm4">
     <visual>
      <geometry>
        <box size="0.08 0.02 0.02"/>
      </geometry>
      <origin rpy="0 0 0" xyz="0.04 0.0 0.0"/>
      <material name="white">
        <color rgba="1 1 1 1"/>
      </material>
    </visual>
    <inertial>
    <origin xyz="0.04 0.01 0.01"/>
      <mass value="0.03"/>
      <inertia ixx="1.0e-9" ixy="0.0" ixz="0.0" iyy="1.0e-9" iyz="0.0" izz="1.0e-9"/>
    </inertial>
     <collision>
      <geometry>
        <box size="0.08 0.02 0.02"/>
      </geometry>
      <origin rpy="0 0 0" xyz="0.04 0.01 0.01"/>
    </collision>
  </link>

    <link name="arm5">
     <visual>
      <geometry>
        <box size="0.08 0.02 0.02"/>
      </geometry>
      <origin rpy="0 0 0" xyz="0.04 0.0 0.0"/>
      <material name="white">
        <color rgba="1 1 1 1"/>
      </material>
    </visual>
    <inertial>
    <origin xyz="0.04 0.01 0.01"/>
      <mass value="0.03"/>
      <inertia ixx="1.0e-9" ixy="0.0" ixz="0.0" iyy="1.0e-9" iyz="0.0" izz="1.0e-9"/>
    </inertial>
     <collision>
      <geometry>
        <box size="0.08 0.02 0.02"/>
      </geometry>
      <origin rpy="0 0 0" xyz="0.048 0.01 0.01"/>
    </collision>
  </link>

    <link name="arm6">
    <visual>
      <geometry>
        <box size="0.08 0.02 0.02"/>
      </geometry>
      <origin rpy="0 0 0" xyz="0.04 0.0 0.0"/>
      <material name="white">
        <color rgba="1 1 1 1"/>
      </material>
    </visual>
    <inertial>
    <origin xyz="0.04 0.01 0.01"/>
      <mass value="0.03"/>
      <inertia ixx="1.0e-9" ixy="0.0" ixz="0.0" iyy="1.0e-9" iyz="0.0" izz="1.0e-9"/>
    </inertial>
     <collision>
      <geometry>
        <box size="0.08 0.02 0.02"/>
      </geometry>
      <origin rpy="0 0 0" xyz="0.045 0.01 0.01"/>
    </collision>
  </link>

  <joint name="body_to_arm1" type="revolute">
    <axis xyz="0 0 1"/>
    <origin rpy="0 0 -0.523" xyz="0.061 -0.035 0"/>
    <parent link="mainbody"/>
    <child link="arm1"/>
    <limit effort="1" velocity="0.5"/>
    <joint_properties damping="0.0" friction="0.0"/>
  </joint>

    <joint name="body_to_arm2" type="revolute">
    <axis xyz="0 0 1"/>
    <origin rpy="0 0 -1.57" xyz="0.0 -0.07 0"/>
    <parent link="mainbody"/>
    <child link="arm2"/>
    <limit effort="1" velocity="0.5"/>
    <joint_properties damping="0.0" friction="0.0"/>
  </joint>

    <joint name="body_to_arm3" type="revolute">
    <axis xyz="0 0 1"/>
    <origin rpy="0 0 -2.617" xyz="-0.061 -0.035 0"/>
    <parent link="mainbody"/>
    <child link="arm3"/>
    <limit effort="1" velocity="0.5"/>
    <joint_properties damping="0.0" friction="0.0"/>
  </joint>

  <joint name="body_to_arm4" type="revolute">
    <axis xyz="0 0 1"/>
    <origin rpy="0 0 2.617" xyz="-0.061 0.035 0"/>
    <parent link="mainbody"/>
    <child link="arm4"/>
    <limit effort="1" velocity="0.5"/>
    <joint_properties damping="0.0" friction="0.0"/>
  </joint>

    <joint name="body_to_arm5" type="revolute">
    <axis xyz="0 0 1"/>
    <origin rpy="0 0 1.57" xyz="0.0 0.07 0"/>
    <parent link="mainbody"/>
    <child link="arm5"/>
    <limit effort="1" velocity="0.5"/>
    <joint_properties damping="0.0" friction="0.0"/>
  </joint>

    <joint name="body_to_arm6" type="revolute">
    <axis xyz="0 0 1"/>
    <origin rpy="0 0 .523" xyz="0.061 0.035 0"/>
    <parent link="mainbody"/>
    <child link="arm6"/>
    <limit effort="1" velocity="0.5"/>
    <joint_properties damping="0.0" friction="0.0"/>
  </joint>

  <joint name="body_to_landinggear" type="fixed">
    <origin rpy="0 0 0" xyz="0.0 0.0 -0.05"/>
    <parent link="mainbody"/>
    <child link="landinggear"/>
  </joint>

  <joint name="arm1_to_prop1" type="fixed">
    <origin rpy="0.3 0 0" xyz="0.06 0.0 0.02"/>
    <parent link="arm1"/>
    <child link="prop1"/>
  </joint>

    <joint name="arm2_to_prop2" type="fixed">
    <origin rpy="-0.3 0 0" xyz="0.06 0.0 0.02"/>
    <parent link="arm2"/>
    <child link="prop2"/>
  </joint>

  <joint name="arm3_to_prop3" type="fixed">
    <origin rpy="0.3 0 0" xyz="0.06 0.0 0.02"/>
    <parent link="arm3"/>
    <child link="prop3"/>
  </joint>

  <joint name="arm4_to_prop4" type="fixed">
    <origin rpy="-0.3 0 0" xyz="0.06 0.0 0.02"/>
    <parent link="arm4"/>
    <child link="prop4"/>
  </joint>

  <joint name="arm5_to_prop5" type="fixed">
    <origin rpy="0.3 0 0" xyz="0.06 0.0 0.02"/>
    <parent link="arm5"/>
    <child link="prop5"/>
  </joint>

  <joint name="arm6_to_prop6" type="fixed">
    <origin rpy="-0.3 0 0" xyz="0.06 0.0 0.02"/>
    <parent link="arm6"/>
    <child link="prop6"/>
  </joint>


</robot>
